<?xml version="1.0" ?>
<!-- A: x is red, y is green, z is blue -->

<robot name="pioneer3at_body" xmlns:xacro="http://ros.org/wiki/xacro">
  <link name="base_link"/>

  <gazebo reference="p3at_front_left_wheel">
    <material value="Gazebo/Black"/>
  </gazebo>

  <gazebo reference="chassis">
    <material value="Gazebo/Red"/>
  </gazebo>

  <gazebo reference="top_plate">
    <material value="Gazebo/Black"/>
  </gazebo>

  <gazebo reference="p3at_front_left_axle">
    <material value="Gazebo/Grey"/>
  </gazebo>

  <gazebo reference="p3at_front_left_hub">
    <material value="Gazebo/Yellow"/>
  </gazebo>

  <!-- Chassis -->
  <link name="chassis">
    <inertial>
      <mass value="20.0"/>
      <origin xyz="0 0 -0.090"/>
      <inertia ixx="0.3338" ixy="0.0" ixz="0.0" iyy="0.4783" iyz="0.0" izz="0.3338"/>
    </inertial>
    <visual>
      <origin rpy="0 0 0" xyz="0 0 0.0"/>
      <geometry name="pioneer_geom">
        <mesh filename="package://p3at_description/meshes/chassis.dae"/>
      </geometry>
      <material name="ChassisRed"/>
    </visual>
    <collision>
      <origin rpy="0 0 0" xyz="0 0 0.0"/>
      <geometry>
        <mesh filename="package://p3at_description/meshes/chassis.dae"/>
      </geometry>
    </collision>
  </link>

  <joint name="base_chassis_joint" type="fixed">
    <origin rpy="0 0 0" xyz="0.00 0 0.177"/>
    <parent link="base_link"/>
    <child link="chassis"/>
  </joint>

  <!-- <plugin
      filename="ignition-gazebo-joint-state-publisher-system"
      name="ignition::gazebo::systems::JointStatePublisher">
      <topic>joint_states</topic>
  </plugin> -->

  <!-- Top -->
  <link name="top_plate">
    <inertial>
      <mass value="0.1"/>
      <origin xyz="-0.025 0 -0.223"/>
      <inertia ixx="1.0" ixy="0.0" ixz="0.0" iyy="1.0" iyz="0.0" izz="1.0"/>
    </inertial>
    <visual>
      <origin rpy="0 0 0" xyz="0 0 0"/>
      <geometry name="pioneer_geom">
        <mesh filename="package://p3at_description/meshes/top.dae"/>
      </geometry>
      <material name="TopBlack">
        <color rgba="0.038 0.038 0.038 1.0"/>
      </material>
    </visual>
    <collision>
      <origin rpy="0 0 0" xyz="0 0 0"/>
      <geometry>
        <box size="0.1 0.1 0.1"/>
      </geometry>
    </collision>
  </link>
  
  <joint name="chassis_top_joint" type="fixed">
    <origin rpy="0 0 0" xyz="0.043 0 0.254"/>
    <parent link="base_link"/>
    <child link="top_plate"/>
  </joint>

  <!-- Front Left Wheel -->
  <link name="p3at_front_left_axle">
    <inertial>
      <mass value="0.1"/>
      <origin xyz="0 0 0"/>
      <inertia ixx="1.0" ixy="0.0" ixz="0.0" iyy="1.0" iyz="0.0" izz="1.0"/>
    </inertial>
    <visual name="front_left_axle">
      <origin rpy="0 0 0" xyz="0 0 0"/>
      <geometry name="pioneer_geom">
        <mesh filename="package://p3at_description/meshes/p3at_meshes/axle.dae"/>
      </geometry>
      <material name="AxleGrey">
        <color rgba="0.5 0.5 0.5 1"/>
      </material>
    </visual>
    <collision>
      <origin rpy="0 0 0" xyz="0 0 0"/>
      <geometry>
        <box size="0.01 0.01 0.01"/>
      </geometry>
    </collision>
  </link>
  
  <joint name="base_front_left_axle_joint" type="fixed">
    <origin rpy="0 0 0" xyz="0.135 0.156 0.111"/>
    <parent link="base_link"/>
    <child link="p3at_front_left_axle"/>
  </joint>

  <link name="p3at_front_left_hub">
    <inertial>
      <mass value="0.1"/>
      <origin xyz="0 0 0"/>
      <inertia ixx="1.0" ixy="0.0" ixz="0.0" iyy="1.0" iyz="0.0" izz="1.0"/>
    </inertial>
    <visual name="front_left_hub">
      <origin rpy="0 0 0" xyz="0 0 0"/>
      <geometry name="pioneer_geom">
        <mesh filename="package://p3at_description/meshes/p3at_meshes/left_hubcap.dae"/>
      </geometry>
      <material name="HubcapYellow">
        <color rgba="1.0 0.811 0.151 1.0"/>
      </material>
    </visual>
    <collision>
      <origin rpy="0 0 0" xyz="0 0 0"/>
      <geometry>
        <box size="0.01 0.01 0.01"/>
      </geometry>
    </collision>
  </link>
  
  <joint name="base_front_left_hub_joint" type="fixed">
    <origin rpy="0 0 0" xyz="0 0.041 0"/>
    <parent link="p3at_front_left_axle"/>
    <child link="p3at_front_left_hub"/>
  </joint>

  <link name="p3at_front_left_wheel">
    <inertial>
      <mass value="0.5"/>
      <origin xyz="0 0 0"/>
      <inertia ixx="0.012411765597" ixy="0" ixz="0" iyy="0.015218160428" iyz="0" izz="0.011763977943"/>
    </inertial>
    <visual name="front_left_wheel">
      <origin rpy="0 0 0" xyz="0 0 0"/>
      <geometry name="pioneer_geom">
        <mesh filename="package://p3at_description/meshes/p3at_meshes/wheel.dae"/>
      </geometry>
      <material name="WheelBlack">
        <color rgba="0.117 0.117 0.117 1"/>
      </material>
    </visual>
    <collision>
      <origin rpy="0 0 0" xyz="0 0 0"/>
      <geometry>
        <mesh filename="package://p3at_description/meshes/p3at_meshes/wheel.dae"/>
        <cylinder length="0.075" radius="0.111"/>
      </geometry>
    </collision>
  </link>

  <joint name="p3at_front_left_wheel_joint" type="continuous">
    <axis xyz="0 1 0"/>
    <anchor xyz="0 0 0"/>
    <origin rpy="0 0 0" xyz="0 0 0"/>
    <parent link="p3at_front_left_hub"/>
    <child link="p3at_front_left_wheel"/>
    <limit effort="100" velocity="100"/>
    <!-- <joint_properties damping="0.7"/> -->
  </joint>

  <!-- Front Right Wheel -->
  <link name="p3at_front_right_axle">
    <inertial>
      <mass value="0.1"/>
      <origin xyz="0 0 0"/>
      <inertia ixx="1.0" ixy="0.0" ixz="0.0" iyy="1.0" iyz="0.0" izz="1.0"/>
    </inertial>
    <visual name="front_right_axle">
      <origin rpy="0 0 0" xyz="0 0 0"/>
      <geometry name="pioneer_geom">
        <mesh filename="package://p3at_description/meshes/p3at_meshes/axle.dae"/>
      </geometry>
      <material name="AxleGrey">
        <color rgba="0.5 0.5 0.5 1"/>
      </material>
    </visual>
    <collision>
      <origin rpy="0 0 0" xyz="0 0 0"/>
      <geometry>
        <box size="0.01 0.01 0.01"/>
      </geometry>
    </collision>
  </link>

  <joint name="base_front_right_axle_joint" type="fixed">
    <origin rpy="0 0 0" xyz="0.135 -0.156 0.111"/>
    <parent link="base_link"/>
    <child link="p3at_front_right_axle"/>
  </joint>

  <link name="p3at_front_right_hub">
    <inertial>
      <mass value="0.1"/>
      <origin xyz="0 0 0"/>
      <inertia ixx="1.0" ixy="0.0" ixz="0.0" iyy="1.0" iyz="0.0" izz="1.0"/>
    </inertial>
    <visual name="front_right_hub">
      <origin rpy="0 0 0" xyz="0 0 0"/>
      <geometry name="pioneer_geom">
        <mesh filename="package://p3at_description/meshes/p3at_meshes/left_hubcap.dae"/>
      </geometry>
      <material name="HubcapYellow">
        <color rgba="1.0 0.811 0.151 1.0"/>
      </material>
    </visual>
    <collision>
      <origin rpy="0 0 0" xyz="0 0 0"/>
      <geometry>
        <box size="0.01 0.01 0.01"/>
      </geometry>
    </collision>
  </link>
  
  <joint name="base_front_right_hub_joint" type="fixed">
    <origin rpy="0 0 0" xyz="0 -0.041 0"/>
    <parent link="p3at_front_right_axle"/>
    <child link="p3at_front_right_hub"/>
  </joint>

  <link name="p3at_front_right_wheel">
    <inertial>
      <mass value="0.5"/>
      <origin xyz="0 0 0"/>
      <inertia ixx="0.012411765597" ixy="0" ixz="0" iyy="0.015218160428" iyz="0" izz="0.011763977943"/>
    </inertial>
    <visual name="front_right_wheel">
      <origin rpy="0 0 0" xyz="0 0 0"/>
      <geometry name="pioneer_geom">
        <mesh filename="package://p3at_description/meshes/p3at_meshes/wheel.dae"/>
      </geometry>
      <material name="WheelBlack">
        <color rgba="0.117 0.117 0.117 1"/>
      </material>
    </visual>
    <collision>
      <origin rpy="0 0 0" xyz="0 0 0"/>
      <geometry>
        <mesh filename="package://p3at_description/meshes/p3at_meshes/wheel.dae"/>
        <cylinder length="0.075" radius="0.111"/>
      </geometry>
    </collision>
  </link>

  <joint name="p3at_front_right_wheel_joint" type="continuous">
    <axis xyz="0 1 0"/>
    <anchor xyz="0 0 0"/>
    <origin rpy="0 0 0" xyz="0 0 0"/>
    <parent link="p3at_front_right_hub"/>
    <child link="p3at_front_right_wheel"/>
    <limit effort="100" velocity="100"/>
    <!-- <joint_properties damping="0.7"/> -->
  </joint>

  <!-- Back Left Wheel -->
  <link name="p3at_back_left_axle">
    <inertial>
      <mass value="0.1"/>
      <origin xyz="0 0 0"/>
      <inertia ixx="1.0" ixy="0.0" ixz="0.0" iyy="1.0" iyz="0.0" izz="1.0"/>
    </inertial>
    <visual name="back_left_axle">
      <origin rpy="0 0 0" xyz="0 0 0"/>
      <geometry name="pioneer_geom">
        <mesh filename="package://p3at_description/meshes/p3at_meshes/axle.dae"/>
      </geometry>
      <material name="AxleGrey">
        <color rgba="0.5 0.5 0.5 1"/>
      </material>
    </visual>
    <collision>
      <origin rpy="0 0 0" xyz="0 0 0"/>
      <geometry>
        <box size="0.01 0.01 0.01"/>
      </geometry>
    </collision>
  </link>

  <joint name="base_back_left_axle_joint" type="fixed">
    <origin rpy="0 0 0" xyz="-0.129 0.156 0.111"/>
    <parent link="base_link"/>
    <child link="p3at_back_left_axle"/>
  </joint>

  <link name="p3at_back_left_hub">
    <inertial>
      <mass value="0.1"/>
      <origin xyz="0 0 0"/>
      <inertia ixx="1.0" ixy="0.0" ixz="0.0" iyy="1.0" iyz="0.0" izz="1.0"/>
    </inertial>
    <visual name="back_left_hub">
      <origin rpy="0 0 0" xyz="0 0 0"/>
      <geometry name="pioneer_geom">
        <mesh filename="package://p3at_description/meshes/p3at_meshes/left_hubcap.dae"/>
      </geometry>
      <material name="HubcapYellow">
        <color rgba="1.0 0.811 0.151 1.0"/>
      </material>
    </visual>
    <collision>
      <origin rpy="0 0 0" xyz="0 0 0"/>
      <geometry>
        <box size="0.01 0.01 0.01"/>
      </geometry>
    </collision>
  </link>
  
  <joint name="base_back_left_hub_joint" type="fixed">
    <origin rpy="0 0 0" xyz="0 0.041 0"/>
    <parent link="p3at_back_left_axle"/>
    <child link="p3at_back_left_hub"/>
  </joint>

  <link name="p3at_back_left_wheel">
    <inertial>
      <mass value="0.5"/>
      <origin xyz="0 0 0"/>
      <inertia ixx="0.012411765597" ixy="0" ixz="0" iyy="0.015218160428" iyz="0" izz="0.011763977943"/>
    </inertial>
    <visual name="back_left_wheel">
      <origin rpy="0 0 0" xyz="0 0 0"/>
      <geometry name="pioneer_geom">
        <mesh filename="package://p3at_description/meshes/p3at_meshes/wheel.dae"/>
      </geometry>
      <material name="WheelBlack">
        <color rgba="0.117 0.117 0.117 1"/>
      </material>
    </visual>
    <collision>
      <origin rpy="0 0 0" xyz="0 0 0"/>
      <geometry>
        <mesh filename="package://p3at_description/meshes/p3at_meshes/wheel.dae"/>
        <cylinder length="0.075" radius="0.111"/>
      </geometry>
    </collision>
  </link>

  <joint name="p3at_back_left_wheel_joint" type="continuous">
    <axis xyz="0 1 0"/>
    <anchor xyz="0 0 0"/>
    <origin rpy="0 0 0" xyz="0 0 0"/>
    <parent link="p3at_back_left_hub"/>
    <child link="p3at_back_left_wheel"/>
    <limit effort="100" velocity="100"/>
    <!-- <joint_properties damping="0.7"/> -->
  </joint>

  <!-- Back Right Wheel -->
  <link name="p3at_back_right_axle">
    <inertial>
      <mass value="0.1"/>
      <origin xyz="0 0 0"/>
      <inertia ixx="1.0" ixy="0.0" ixz="0.0" iyy="1.0" iyz="0.0" izz="1.0"/>
    </inertial>
    <visual name="back_right_axle">
      <origin rpy="0 0 0" xyz="0 0 0"/>
      <geometry name="pioneer_geom">
        <mesh filename="package://p3at_description/meshes/p3at_meshes/axle.dae"/>
      </geometry>
      <material name="AxleGrey">
        <color rgba="0.5 0.5 0.5 1"/>
      </material>
    </visual>
    <collision>
      <origin rpy="0 0 0" xyz="0 0 0"/>
      <geometry>
        <box size="0.01 0.01 0.01"/>
      </geometry>
    </collision>
  </link>

  <joint name="base_back_right_axle_joint" type="fixed">
    <origin rpy="0 0 0" xyz="-0.129 -0.156 0.111"/>
    <parent link="base_link"/>
    <child link="p3at_back_right_axle"/>
  </joint>

  <link name="p3at_back_right_hub">
    <inertial>
      <mass value="0.1"/>
      <origin xyz="0 0 0"/>
      <inertia ixx="1.0" ixy="0.0" ixz="0.0" iyy="1.0" iyz="0.0" izz="1.0"/>
    </inertial>
    <visual name="back_right_hub">
      <origin rpy="0 0 0" xyz="0 0 0"/>
      <geometry name="pioneer_geom">
        <mesh filename="package://p3at_description/meshes/p3at_meshes/left_hubcap.dae"/>
      </geometry>
      <material name="HubcapYellow">
        <color rgba="1.0 0.811 0.151 1.0"/>
      </material>
    </visual>
    <collision>
      <origin rpy="0 0 0" xyz="0 0 0"/>
      <geometry>
        <box size="0.01 0.01 0.01"/>
      </geometry>
    </collision>
  </link>
  
  <joint name="base_back_right_hub_joint" type="fixed">
    <origin rpy="0 0 0" xyz="0 -0.041 0"/>
    <parent link="p3at_back_right_axle"/>
    <child link="p3at_back_right_hub"/>
  </joint>

  <link name="p3at_back_right_wheel">
    <inertial>
      <mass value="0.5"/>
      <origin xyz="0 0 0"/>
      <inertia ixx="0.012411765597" ixy="0" ixz="0" iyy="0.015218160428" iyz="0" izz="0.011763977943"/>
    </inertial>
    <visual name="back_right_wheel">
      <origin rpy="0 0 0" xyz="0 0 0"/>
      <geometry name="pioneer_geom">
        <mesh filename="package://p3at_description/meshes/p3at_meshes/wheel.dae"/>
      </geometry>
      <material name="WheelBlack">
        <color rgba="0.117 0.117 0.117 1"/>
      </material>
    </visual>
    <collision>
      <origin rpy="0 0 0" xyz="0 0 0"/>
      <geometry>
        <mesh filename="package://p3at_description/meshes/p3at_meshes/wheel.dae"/>
        <cylinder length="0.075" radius="0.111"/>
      </geometry>
    </collision>
  </link>

  <joint name="p3at_back_right_wheel_joint" type="continuous">
    <axis xyz="0 1 0"/>
    <anchor xyz="0 0 0"/>
    <origin rpy="0 0 0" xyz="0 0 0"/>
    <parent link="p3at_back_right_hub"/>
    <child link="p3at_back_right_wheel"/>
    <limit effort="100" velocity="100"/>
    <!-- <joint_properties damping="0.7"/> -->
  </joint>

  <!-- lidar -->

  <joint name="laser_joint" type="fixed">
    <parent link="chassis" />
    <child link="laser_frame" />
    <origin xyz="0.2 0 0.104" rpy="0 0 0"/>
  </joint>

  <link name="laser_frame">
    <collision>
      <origin xyz="0 0 0" rpy="0 0 0"/>
      <geometry>
        <box size="0.01 0.01 0.01"/>
      </geometry>
    </collision>
    <visual>
      <origin xyz="0 0 0" rpy="0 0 0"/> 
      <geometry>
        <mesh filename="package://p3at_description/meshes/hokuyo1.dae"/>
      </geometry>
    </visual>
    <inertial>
      <mass value="1e-5" />
      <origin xyz="0 0 0" rpy="0 0 0"/>
      <inertia ixx="1e-6" ixy="0" ixz="0" iyy="1e-6" iyz="0" izz="1e-6" />
    </inertial>
  </link>

  <!-- Camera -->
  <joint name="cam_joint" type="fixed">
    <parent link="chassis" />
    <child link="cam_frame" />
    <origin xyz="0.24 0 0.084" rpy="0 0 0"/>
  </joint>

  <link name="cam_frame">
    <visual>
      <origin xyz="0 0 0" rpy="0 0 0"/> 
      <geometry>
        <box size="0.01 0.05 0.01"/>
      </geometry>
      <material name="greenCam">
        <color rgba="0 1.0 0 1.0"/>
      </material>
    </visual>
  </link>

  <joint name="cam_optical_joint" type="fixed">
    <parent link="cam_frame" />
    <child link="cam_optical_link" />
    <origin xyz="0.3 0 0.2" rpy="-1.65 0 -1.65"/>
  </joint>

  <link name="cam_optical_link"></link>

  <gazebo reference="laser_frame">
    <sensor name='gpu_lidar' type='gpu_lidar'>"
      <pose relative_to='laser_frame'>0 0 0 0 0 0</pose>
      <topic>lidar</topic>
      <update_rate>5</update_rate>
      <ray>
          <scan>
              <horizontal>
                  <samples>541</samples>
                  <resolution>1</resolution>
                  <min_angle>-1.570874810218811</min_angle>
                  <max_angle>1.5704036951065063</max_angle>
              </horizontal>
              <vertical>
                  <samples>1</samples>
                  <resolution>0.01</resolution>
                  <min_angle>0</min_angle>
                  <max_angle>0</max_angle>
              </vertical>
          </scan>
          <range>
              <min>0.08</min>
              <max>10.0</max>
              <resolution>0.01</resolution>
          </range>
          <noise>
            <type>gaussian</type>
            <mean>0.0</mean>
            <stddev>0.01</stddev>
          </noise>
      </ray>
      <always_on>1</always_on>
      <visualize>true</visualize>
      <plugin name="lidar_scan" filename="libgazebo_ros_ray_sensor.so">
        <ros>
          <remapping>~/out:=scan</remapping>
        </ros>
        <output_type>sensor_msgs/LaserScan</output_type>
        <frame_name>laser_frame</frame_name>
      </plugin>
    </sensor>
  </gazebo>

  <gazebo reference="p3at_front_left_wheel">
      <kp>10000000.0</kp> <!--contact stiffness-->
      <kd>100.0</kd> <!--damping-->
  </gazebo>

  <gazebo reference="p3at_front_right_wheel">
      <kp>10000000.0</kp> <!--contact stiffness-->
      <kd>100.0</kd> <!--damping-->
  </gazebo>

  <gazebo reference="p3at_back_left_wheel">
      <kp>10000000.0</kp> <!--contact stiffness-->
      <kd>100.0</kd> <!--damping-->
  </gazebo>

  <gazebo reference="p3at_back_right_wheel">
      <kp>10000000.0</kp> <!--contact stiffness-->
      <kd>100.0</kd> <!--damping-->
  </gazebo>

  <gazebo>
    <plugin
      filename="libignition-gazebo-diff-drive-system.so"
      name="ignition::gazebo::systems::DiffDrive">
      <left_joint>p3at_front_left_wheel_joint</left_joint>
      <left_joint>p3at_back_left_wheel_joint</left_joint>
      <right_joint>p3at_back_right_wheel_joint</right_joint>
      <right_joint>p3at_front_right_wheel_joint</right_joint>
      <wheel_separation>0.268</wheel_separation>
      <wheel_radius>0.111</wheel_radius>
      <odom_publish_frequency>20</odom_publish_frequency>
      <topic>cmd_vel</topic>
      <frame_id>odom</frame_id>
    </plugin>
  </gazebo> 

  <!--gazebo>
    <plugin name="p3at_controller_front" filename="libgazebo_ros_diff_drive.so">
      <update_rate>50</update_rate>
      <num_wheel_pairs>2</num_wheel_pairs>

      <left_joint>p3at_front_left_wheel_joint</left_joint>
      <left_joint>p3at_back_left_wheel_joint</left_joint>
      <right_joint>p3at_front_right_wheel_joint</right_joint>
      <right_joint>p3at_back_right_wheel_joint</right_joint>

      <wheel_separation>0.268</wheel_separation>
      <wheel_diameter>0.222</wheel_diameter>
      <command_topic>cmd_vel</command_topic>

      <publish_odom>true</publish_odom>
      <publish_odom_tf>true</publish_odom_tf>
      <publish_wheel_tf>true</publish_wheel_tf>
      
      <robot_base_frame>base_link</robot_base_frame>
    </plugin>
  </gazebo> -->

  <!-- <gazebo>
    <plugin name="p3at_controller_back" filename="libgazebo_ros_diff_drive.so">
      <update_rate>50</update_rate>

      <left_joint>p3at_front_left_wheel_joint</left_joint>
      <left_joint>p3at_back_left_wheel_joint</left_joint>
      <right_joint>p3at_front_right_wheel_joint</right_joint>
      <right_joint>p3at_back_right_wheel_joint</right_joint>

      <wheel_separation>0.268</wheel_separation>
      <wheel_diameter>0.222</wheel_diameter>
      <command_topic>cmd_vel</command_topic>

      <publish_odom>true</publish_odom>
      <publish_odom_tf>true</publish_odom_tf>
      <publish_wheel_tf>true</publish_wheel_tf>

      <robot_base_frame>base_link</robot_base_frame>
    </plugin>
  </gazebo> -->

  <gazebo reference="cam_frame">
    <material>Gazebo/Blue</material>
    <sensor name='camera' type='camera'>"
      <pose>0 0 0 0 0 0</pose>
      <always_on>1</always_on>
      <visualize>true</visualize>
      <topic>camera</topic>
      <update_rate>10</update_rate>
      <!-- <camera>
        <horizontal_fov>1.089</horizontal_fov>
        <image>
          <format>R8G8B8</format>
          <width>640</width>
          <height>480</height>
        </image>
        <clip>
          <near>0.5</near>
          <far>8.0</far>
        </clip>
      </camera> -->
      <plugin name="p3at_camera" filename="libgazebo_ros_camera.so">
        <frame_name>cam_frame</frame_name>
        <ros>
          <namespace>p3at</namespace>
          <remapping>image_raw:=image</remapping>
          <remapping>camera_info:=info</remapping>
        </ros>
      </plugin>
    </sensor>
  </gazebo>

  <!-- IMU -->
  <gazebo reference="base_link">
    <sensor name="imu_sensor" type="imu">
      <always_on>1</always_on>
      <update_rate>20</update_rate>
      <visualize>true</visualize>
      <plugin name="imu_plugin" filename="libgazebo_ros_imu_sensor.so">
        <ros>
          <namespace>imu</namespace>
          <remapping>~/out:=data_raw</remapping>
        </ros>
      </plugin>
    </sensor>
  </gazebo>

</robot>
  
